import { describe, it, expect, beforeEach, vi } from 'vitest'
import { ReviewManager } from '../services/review-manager'

describe('Review Workflow - Security & Error Handling', () => {
  let reviewManager: ReviewManager

  beforeEach(() => {
    reviewManager = new ReviewManager(false)
  })

  describe('4.5-E2E-010: Unauthorized review attempt', () => {
    it('should prevent unauthorized access to review operations', async () => {
      // Mock user authentication
      const mockUser = { id: 'user-1', role: 'viewer' } // Non-admin user
      const mockAdminUser = { id: 'admin-1', role: 'admin' }

      // Mock authorization check
      const checkReviewPermission = (user: typeof mockUser, operation: string) => {
        const requiredPermissions = {
          'start_review': ['admin', 'reviewer'],
          'accept_changes': ['admin', 'reviewer'],
          'reject_changes': ['admin', 'reviewer'],
          'rollback': ['admin']
        }

        const allowed = requiredPermissions[operation as keyof typeof requiredPermissions] || []
        return allowed.includes(user.role)
      }

      // Test unauthorized review start
      expect(checkReviewPermission(mockUser, 'start_review')).toBe(false)
      expect(checkReviewPermission(mockAdminUser, 'start_review')).toBe(true)

      // Test unauthorized acceptance
      expect(checkReviewPermission(mockUser, 'accept_changes')).toBe(false)
      expect(checkReviewPermission(mockAdminUser, 'accept_changes')).toBe(true)

      // Test unauthorized rollback
      expect(checkReviewPermission(mockUser, 'rollback')).toBe(false)
      expect(checkReviewPermission(mockAdminUser, 'rollback')).toBe(true)
    })

    it('should validate review ownership before modifications', async () => {
      const mockReview = {
        id: 'review-1',
        metadata: {
          createdBy: 'user-1',
          createdAt: new Date()
        },
        status: 'reviewing'
      }

      const checkOwnership = (review: typeof mockReview, currentUserId: string) => {
        return review.metadata.createdBy === currentUserId
      }

      // Owner can modify
      expect(checkOwnership(mockReview, 'user-1')).toBe(true)
      
      // Non-owner cannot modify
      expect(checkOwnership(mockReview, 'user-2')).toBe(false)
    })
  })

  describe('4.5-INT-019: Recovery from partial failure', () => {
    it('should handle partial application failures gracefully', async () => {
      const mockChanges = [
        { id: 'change-1', type: 'CREATE_ENTITY', data: { id: 'entity-1' } },
        { id: 'change-2', type: 'CREATE_ENTITY', data: { id: 'entity-2' } },
        { id: 'change-3', type: 'CREATE_EDGE', data: { id: 'edge-1' } }
      ]

      const applyChanges = async (changes: typeof mockChanges) => {
        const results = []
        const failures = []

        for (let i = 0; i < changes.length; i++) {
          const change = changes[i]
          try {
            // Simulate failure on second change
            if (i === 1) {
              throw new Error('Database constraint violation')
            }
            
            results.push({ changeId: change.id, status: 'success' })
          } catch (error) {
            failures.push({ 
              changeId: change.id, 
              status: 'failed', 
              error: error instanceof Error ? error.message : 'Unknown error'
            })
          }
        }

        return { results, failures }
      }

      const { results, failures } = await applyChanges(mockChanges)

      expect(results).toHaveLength(2) // 2 successful
      expect(failures).toHaveLength(1) // 1 failed
      expect(failures[0].changeId).toBe('change-2')
      expect(failures[0].error).toBe('Database constraint violation')

      // Should have rollback plan for successful changes
      const rollbackPlan = results.map(r => ({
        changeId: r.changeId,
        action: 'rollback'
      }))

      expect(rollbackPlan).toHaveLength(2)
    })

    it('should maintain transaction integrity during failures', async () => {
      const transactionLog = []

      const mockTransaction = {
        begin: () => transactionLog.push('BEGIN'),
        commit: () => transactionLog.push('COMMIT'),
        rollback: () => transactionLog.push('ROLLBACK'),
        addOperation: (op: string) => transactionLog.push(op)
      }

      const processChangesWithTransaction = async (shouldFail: boolean = false) => {
        try {
          mockTransaction.begin()
          mockTransaction.addOperation('CREATE_ENTITY_1')
          mockTransaction.addOperation('CREATE_ENTITY_2')
          
          if (shouldFail) {
            throw new Error('Transaction failure')
          }
          
          mockTransaction.addOperation('CREATE_EDGE_1')
          mockTransaction.commit()
          return { success: true }
        } catch (error) {
          mockTransaction.rollback()
          return { success: false, error: error instanceof Error ? error.message : 'Unknown error' }
        }
      }

      // Test successful transaction
      const successResult = await processChangesWithTransaction(false)
      expect(successResult.success).toBe(true)
      expect(transactionLog).toContain('BEGIN')
      expect(transactionLog).toContain('COMMIT')

      // Reset log
      transactionLog.length = 0

      // Test failed transaction
      const failResult = await processChangesWithTransaction(true)
      expect(failResult.success).toBe(false)
      expect(transactionLog).toContain('BEGIN')
      expect(transactionLog).toContain('ROLLBACK')
      expect(transactionLog).not.toContain('COMMIT')
    })
  })

  describe('4.5-E2E-009: Network failure during acceptance', () => {
    it('should handle network failures with retry logic', async () => {
      let networkCallCount = 0
      const maxRetries = 3

      const mockNetworkCall = async (shouldFail: boolean = false) => {
        networkCallCount++
        
        if (shouldFail && networkCallCount < maxRetries) {
          throw new Error('Network timeout')
        }
        
        return { success: true, data: 'Changes applied successfully' }
      }

      const applyChangesWithRetry = async () => {
        let attempts = 0
        
        while (attempts < maxRetries) {
          try {
            const result = await mockNetworkCall(attempts < 2) // Fail first 2 attempts
            return result
          } catch (error) {
            attempts++
            if (attempts >= maxRetries) {
              throw error
            }
            // Wait before retry (simulate exponential backoff)
            await new Promise(resolve => setTimeout(resolve, Math.pow(2, attempts) * 100))
          }
        }
      }

      const result = await applyChangesWithRetry()
      
      expect(result.success).toBe(true)
      expect(networkCallCount).toBe(3) // Should have retried 3 times
    })

    it('should queue operations during network outage', async () => {
      const operationQueue: Array<{ id: string, operation: string, timestamp: Date }> = []
      let isOnline = false

      const queueOperation = (id: string, operation: string) => {
        operationQueue.push({
          id,
          operation,
          timestamp: new Date()
        })
      }

      const processQueue = async () => {
        if (!isOnline) {
          return { processed: 0, queued: operationQueue.length }
        }

        const processed = operationQueue.splice(0, 3) // Process in batches
        return { processed: processed.length, queued: operationQueue.length }
      }

      // Queue operations while offline
      queueOperation('op-1', 'ACCEPT_CHANGE')
      queueOperation('op-2', 'ACCEPT_CHANGE') 
      queueOperation('op-3', 'REJECT_CHANGE')
      queueOperation('op-4', 'ACCEPT_CHANGE')

      expect(operationQueue).toHaveLength(4)

      // Try to process while offline
      let result = await processQueue()
      expect(result.processed).toBe(0)
      expect(result.queued).toBe(4)

      // Come back online and process
      isOnline = true
      result = await processQueue()
      expect(result.processed).toBe(3)
      expect(result.queued).toBe(1)

      // Process remaining
      result = await processQueue()
      expect(result.processed).toBe(1)
      expect(result.queued).toBe(0)
    })
  })

  describe('4.5-INT-017: Handle concurrent reviews', () => {
    it('should detect and handle concurrent review modifications', async () => {
      const mockReview = {
        id: 'review-1',
        version: 1,
        lastModified: new Date('2025-01-01T10:00:00Z'),
        status: 'reviewing'
      }

      const checkConcurrentModification = (
        review: typeof mockReview,
        expectedVersion: number,
        expectedTimestamp: Date
      ) => {
        return {
          hasConflict: review.version !== expectedVersion || 
                       review.lastModified.getTime() !== expectedTimestamp.getTime(),
          currentVersion: review.version,
          currentTimestamp: review.lastModified
        }
      }

      // Simulate User A's expected state
      const userAExpectedVersion = 1
      const userAExpectedTimestamp = new Date('2025-01-01T10:00:00Z')

      // Simulate User B modifies the review first
      mockReview.version = 2
      mockReview.lastModified = new Date('2025-01-01T10:05:00Z')

      // User A tries to modify - should detect conflict
      const conflictCheck = checkConcurrentModification(
        mockReview,
        userAExpectedVersion,
        userAExpectedTimestamp
      )

      expect(conflictCheck.hasConflict).toBe(true)
      expect(conflictCheck.currentVersion).toBe(2)
      expect(conflictCheck.currentTimestamp.getTime()).toBeGreaterThan(
        userAExpectedTimestamp.getTime()
      )
    })

    it('should merge compatible concurrent changes', async () => {
      const baseReview = {
        id: 'review-1',
        changes: ['change-1', 'change-2', 'change-3'],
        decisions: new Map(),
        annotations: new Map()
      }

      // User A adds annotation to change-1
      const userAChanges = {
        annotations: new Map([['change-1', 'User A comment']])
      }

      // User B adds decision to change-2  
      const userBChanges = {
        decisions: new Map([['change-2', 'accept']])
      }

      // Merge compatible changes
      const mergedReview = {
        ...baseReview,
        decisions: new Map([...baseReview.decisions, ...userBChanges.decisions]),
        annotations: new Map([...baseReview.annotations, ...userAChanges.annotations])
      }

      expect(mergedReview.decisions.has('change-2')).toBe(true)
      expect(mergedReview.annotations.has('change-1')).toBe(true)
      expect(mergedReview.decisions.get('change-2')).toBe('accept')
      expect(mergedReview.annotations.get('change-1')).toBe('User A comment')
    })
  })

  describe('Storage and Data Integrity', () => {
    it('should handle localStorage quota exceeded gracefully', async () => {
      const mockStorage = {
        quota: 5000, // 5KB limit
        used: 4500,   // Nearly full
        setItem: vi.fn((key: string, value: string) => {
          const size = key.length + value.length
          if (mockStorage.used + size > mockStorage.quota) {
            throw new Error('QuotaExceededError')
          }
          mockStorage.used += size
        }),
        removeItem: vi.fn((key: string) => {
          // Simulate freeing space
          mockStorage.used = Math.max(0, mockStorage.used - 100)
        })
      }

      const saveReviewData = (data: string) => {
        try {
          mockStorage.setItem('review-data', data)
          return { success: true }
        } catch (error) {
          if (error instanceof Error && error.message === 'QuotaExceededError') {
            // Clean up old data
            mockStorage.removeItem('old-review-1')
            mockStorage.removeItem('old-review-2')
            
            // Retry
            try {
              mockStorage.setItem('review-data', data)
              return { success: true, cleanupPerformed: true }
            } catch (retryError) {
              return { success: false, error: 'Storage quota exceeded after cleanup' }
            }
          }
          return { success: false, error: error instanceof Error ? error.message : 'Unknown error' }
        }
      }

      // Try to save large data that exceeds quota
      const largeData = 'x'.repeat(1000)
      const result = saveReviewData(largeData)

      expect(result.success).toBe(true)
      expect(result).toHaveProperty('cleanupPerformed')
    })
  })
})